2021-02-04 12:33:02,149:ERROR:error while consuming ws messages: 'super' object has no attribute 'price'
2021-02-04 12:47:02,246:ERROR:error while consuming ws messages: local variable 'response' referenced before assignment
2021-02-04 12:54:02,390:ERROR:error while consuming ws messages: bracket orders support only "day" or "gtc" time_in_force
2021-02-04 12:55:02,395:ERROR:error while consuming ws messages: bracket orders support only "day" or "gtc" time_in_force
2021-02-04 12:56:02,830:ERROR:error while consuming ws messages: bracket orders support only "day" or "gtc" time_in_force
2021-02-04 12:57:02,511:ERROR:error while consuming ws messages: bracket orders support only "day" or "gtc" time_in_force
2021-02-05 09:10:02,385:ERROR:error while consuming ws messages: bracket orders support only "day" or "gtc" time_in_force
2021-02-05 09:11:02,600:ERROR:error while consuming ws messages: bracket orders support only "day" or "gtc" time_in_force
2021-02-05 09:13:02,387:ERROR:error while consuming ws messages: bracket orders support only "day" or "gtc" time_in_force
2021-02-05 09:14:02,814:ERROR:error while consuming ws messages: bracket orders support only "day" or "gtc" time_in_force
2021-02-05 09:15:02,483:ERROR:error while consuming ws messages: bracket orders support only "day" or "gtc" time_in_force
2021-02-05 09:17:02,419:ERROR:error while consuming ws messages: client_order_id must be unique
2021-02-05 09:18:02,367:ERROR:error while consuming ws messages: client_order_id must be unique
2021-02-05 09:19:02,509:ERROR:error while consuming ws messages: client_order_id must be unique
2021-02-05 09:33:02,528:ERROR:error while consuming ws messages: client_order_id must be unique
2021-02-05 09:34:02,467:ERROR:error while consuming ws messages: client_order_id must be unique
2021-02-05 09:35:02,670:ERROR:error while consuming ws messages: client_order_id must be unique
2021-02-05 09:36:02,562:ERROR:error while consuming ws messages: client_order_id must be unique
2021-02-05 09:37:02,587:ERROR:error while consuming ws messages: client_order_id must be unique
2021-02-05 09:39:02,295:ERROR:error while consuming ws messages: client_order_id must be unique
2021-02-05 09:41:02,411:ERROR:error while consuming ws messages: client_order_id must be unique
2021-02-05 09:45:02,417:ERROR:order not sent
Traceback (most recent call last):
  File "/usr/local/lib/python3.7/site-packages/alpaca_trade_api/rest.py", line 146, in _one_request
    resp.raise_for_status()
  File "/usr/lib/python3.7/site-packages/requests/models.py", line 940, in raise_for_status
    raise HTTPError(http_error_msg, response=self)
requests.exceptions.HTTPError: 422 Client Error: Unprocessable Entity for url: https://paper-api.alpaca.markets/v2/orders

During handling of the above exception, another exception occurred:

Traceback (most recent call last):
  File "/home/will/Documents/Development/Alpaca/python/example.py", line 94, in forceOrd
    client_order_id="0009"
  File "/usr/local/lib/python3.7/site-packages/alpaca_trade_api/rest.py", line 322, in submit_order
    resp = self.post('/orders', params)
  File "/usr/local/lib/python3.7/site-packages/alpaca_trade_api/rest.py", line 165, in post
    return self._request('POST', path, data)
  File "/usr/local/lib/python3.7/site-packages/alpaca_trade_api/rest.py", line 125, in _request
    return self._one_request(method, url, opts, retry)
  File "/usr/local/lib/python3.7/site-packages/alpaca_trade_api/rest.py", line 154, in _one_request
    raise APIError(error, http_error)
alpaca_trade_api.rest.APIError: client_order_id must be unique
2021-02-05 09:45:02,422:ERROR:error while consuming ws messages: local variable 'res' referenced before assignment
2021-02-05 10:08:02,283:ERROR:ORDER NOT SENT
Traceback (most recent call last):
  File "/usr/local/lib/python3.7/site-packages/alpaca_trade_api/rest.py", line 146, in _one_request
    resp.raise_for_status()
  File "/usr/lib/python3.7/site-packages/requests/models.py", line 940, in raise_for_status
    raise HTTPError(http_error_msg, response=self)
requests.exceptions.HTTPError: 422 Client Error: Unprocessable Entity for url: https://paper-api.alpaca.markets/v2/orders

During handling of the above exception, another exception occurred:

Traceback (most recent call last):
  File "/home/will/Documents/Development/Alpaca/python/example.py", line 125, in send_order
    take_profit=dict(limit_price=str(tp)),
  File "/usr/local/lib/python3.7/site-packages/alpaca_trade_api/rest.py", line 322, in submit_order
    resp = self.post('/orders', params)
  File "/usr/local/lib/python3.7/site-packages/alpaca_trade_api/rest.py", line 165, in post
    return self._request('POST', path, data)
  File "/usr/local/lib/python3.7/site-packages/alpaca_trade_api/rest.py", line 125, in _request
    return self._one_request(method, url, opts, retry)
  File "/usr/local/lib/python3.7/site-packages/alpaca_trade_api/rest.py", line 154, in _one_request
    raise APIError(error, http_error)
alpaca_trade_api.rest.APIError: limit orders require a limit price
2021-02-05 10:09:02,327:ERROR:ORDER NOT SENT
Traceback (most recent call last):
  File "/usr/local/lib/python3.7/site-packages/alpaca_trade_api/rest.py", line 146, in _one_request
    resp.raise_for_status()
  File "/usr/lib/python3.7/site-packages/requests/models.py", line 940, in raise_for_status
    raise HTTPError(http_error_msg, response=self)
requests.exceptions.HTTPError: 422 Client Error: Unprocessable Entity for url: https://paper-api.alpaca.markets/v2/orders

During handling of the above exception, another exception occurred:

Traceback (most recent call last):
  File "/home/will/Documents/Development/Alpaca/python/example.py", line 125, in send_order
    take_profit=dict(limit_price=str(tp)),
  File "/usr/local/lib/python3.7/site-packages/alpaca_trade_api/rest.py", line 322, in submit_order
    resp = self.post('/orders', params)
  File "/usr/local/lib/python3.7/site-packages/alpaca_trade_api/rest.py", line 165, in post
    return self._request('POST', path, data)
  File "/usr/local/lib/python3.7/site-packages/alpaca_trade_api/rest.py", line 125, in _request
    return self._one_request(method, url, opts, retry)
  File "/usr/local/lib/python3.7/site-packages/alpaca_trade_api/rest.py", line 154, in _one_request
    raise APIError(error, http_error)
alpaca_trade_api.rest.APIError: limit orders require a limit price
2021-02-05 10:10:02,434:ERROR:ORDER NOT SENT
Traceback (most recent call last):
  File "/usr/local/lib/python3.7/site-packages/alpaca_trade_api/rest.py", line 146, in _one_request
    resp.raise_for_status()
  File "/usr/lib/python3.7/site-packages/requests/models.py", line 940, in raise_for_status
    raise HTTPError(http_error_msg, response=self)
requests.exceptions.HTTPError: 422 Client Error: Unprocessable Entity for url: https://paper-api.alpaca.markets/v2/orders

During handling of the above exception, another exception occurred:

Traceback (most recent call last):
  File "/home/will/Documents/Development/Alpaca/python/example.py", line 125, in send_order
    take_profit=dict(limit_price=str(tp)),
  File "/usr/local/lib/python3.7/site-packages/alpaca_trade_api/rest.py", line 322, in submit_order
    resp = self.post('/orders', params)
  File "/usr/local/lib/python3.7/site-packages/alpaca_trade_api/rest.py", line 165, in post
    return self._request('POST', path, data)
  File "/usr/local/lib/python3.7/site-packages/alpaca_trade_api/rest.py", line 125, in _request
    return self._one_request(method, url, opts, retry)
  File "/usr/local/lib/python3.7/site-packages/alpaca_trade_api/rest.py", line 154, in _one_request
    raise APIError(error, http_error)
alpaca_trade_api.rest.APIError: limit orders require a limit price
2021-02-05 10:11:02,455:ERROR:ORDER NOT SENT
Traceback (most recent call last):
  File "/usr/local/lib/python3.7/site-packages/alpaca_trade_api/rest.py", line 146, in _one_request
    resp.raise_for_status()
  File "/usr/lib/python3.7/site-packages/requests/models.py", line 940, in raise_for_status
    raise HTTPError(http_error_msg, response=self)
requests.exceptions.HTTPError: 422 Client Error: Unprocessable Entity for url: https://paper-api.alpaca.markets/v2/orders

During handling of the above exception, another exception occurred:

Traceback (most recent call last):
  File "/home/will/Documents/Development/Alpaca/python/example.py", line 125, in send_order
    take_profit=dict(limit_price=str(tp)),
  File "/usr/local/lib/python3.7/site-packages/alpaca_trade_api/rest.py", line 322, in submit_order
    resp = self.post('/orders', params)
  File "/usr/local/lib/python3.7/site-packages/alpaca_trade_api/rest.py", line 165, in post
    return self._request('POST', path, data)
  File "/usr/local/lib/python3.7/site-packages/alpaca_trade_api/rest.py", line 125, in _request
    return self._one_request(method, url, opts, retry)
  File "/usr/local/lib/python3.7/site-packages/alpaca_trade_api/rest.py", line 154, in _one_request
    raise APIError(error, http_error)
alpaca_trade_api.rest.APIError: limit orders require a limit price
2021-02-05 10:12:02,338:ERROR:ORDER NOT SENT
Traceback (most recent call last):
  File "/usr/local/lib/python3.7/site-packages/alpaca_trade_api/rest.py", line 146, in _one_request
    resp.raise_for_status()
  File "/usr/lib/python3.7/site-packages/requests/models.py", line 940, in raise_for_status
    raise HTTPError(http_error_msg, response=self)
requests.exceptions.HTTPError: 422 Client Error: Unprocessable Entity for url: https://paper-api.alpaca.markets/v2/orders

During handling of the above exception, another exception occurred:

Traceback (most recent call last):
  File "/home/will/Documents/Development/Alpaca/python/example.py", line 125, in send_order
    take_profit=dict(limit_price=str(tp)),
  File "/usr/local/lib/python3.7/site-packages/alpaca_trade_api/rest.py", line 322, in submit_order
    resp = self.post('/orders', params)
  File "/usr/local/lib/python3.7/site-packages/alpaca_trade_api/rest.py", line 165, in post
    return self._request('POST', path, data)
  File "/usr/local/lib/python3.7/site-packages/alpaca_trade_api/rest.py", line 125, in _request
    return self._one_request(method, url, opts, retry)
  File "/usr/local/lib/python3.7/site-packages/alpaca_trade_api/rest.py", line 154, in _one_request
    raise APIError(error, http_error)
alpaca_trade_api.rest.APIError: limit orders require a limit price
2021-02-05 10:13:02,462:ERROR:ORDER NOT SENT
Traceback (most recent call last):
  File "/usr/local/lib/python3.7/site-packages/alpaca_trade_api/rest.py", line 146, in _one_request
    resp.raise_for_status()
  File "/usr/lib/python3.7/site-packages/requests/models.py", line 940, in raise_for_status
    raise HTTPError(http_error_msg, response=self)
requests.exceptions.HTTPError: 422 Client Error: Unprocessable Entity for url: https://paper-api.alpaca.markets/v2/orders

During handling of the above exception, another exception occurred:

Traceback (most recent call last):
  File "/home/will/Documents/Development/Alpaca/python/example.py", line 125, in send_order
    take_profit=dict(limit_price=str(tp)),
  File "/usr/local/lib/python3.7/site-packages/alpaca_trade_api/rest.py", line 322, in submit_order
    resp = self.post('/orders', params)
  File "/usr/local/lib/python3.7/site-packages/alpaca_trade_api/rest.py", line 165, in post
    return self._request('POST', path, data)
  File "/usr/local/lib/python3.7/site-packages/alpaca_trade_api/rest.py", line 125, in _request
    return self._one_request(method, url, opts, retry)
  File "/usr/local/lib/python3.7/site-packages/alpaca_trade_api/rest.py", line 154, in _one_request
    raise APIError(error, http_error)
alpaca_trade_api.rest.APIError: limit orders require a limit price
2021-02-05 10:14:02,537:ERROR:ORDER NOT SENT
Traceback (most recent call last):
  File "/usr/local/lib/python3.7/site-packages/alpaca_trade_api/rest.py", line 146, in _one_request
    resp.raise_for_status()
  File "/usr/lib/python3.7/site-packages/requests/models.py", line 940, in raise_for_status
    raise HTTPError(http_error_msg, response=self)
requests.exceptions.HTTPError: 422 Client Error: Unprocessable Entity for url: https://paper-api.alpaca.markets/v2/orders

During handling of the above exception, another exception occurred:

Traceback (most recent call last):
  File "/home/will/Documents/Development/Alpaca/python/example.py", line 125, in send_order
    take_profit=dict(limit_price=str(tp)),
  File "/usr/local/lib/python3.7/site-packages/alpaca_trade_api/rest.py", line 322, in submit_order
    resp = self.post('/orders', params)
  File "/usr/local/lib/python3.7/site-packages/alpaca_trade_api/rest.py", line 165, in post
    return self._request('POST', path, data)
  File "/usr/local/lib/python3.7/site-packages/alpaca_trade_api/rest.py", line 125, in _request
    return self._one_request(method, url, opts, retry)
  File "/usr/local/lib/python3.7/site-packages/alpaca_trade_api/rest.py", line 154, in _one_request
    raise APIError(error, http_error)
alpaca_trade_api.rest.APIError: limit orders require a limit price
2021-02-05 10:15:02,351:ERROR:ORDER NOT SENT
Traceback (most recent call last):
  File "/usr/local/lib/python3.7/site-packages/alpaca_trade_api/rest.py", line 146, in _one_request
    resp.raise_for_status()
  File "/usr/lib/python3.7/site-packages/requests/models.py", line 940, in raise_for_status
    raise HTTPError(http_error_msg, response=self)
requests.exceptions.HTTPError: 422 Client Error: Unprocessable Entity for url: https://paper-api.alpaca.markets/v2/orders

During handling of the above exception, another exception occurred:

Traceback (most recent call last):
  File "/home/will/Documents/Development/Alpaca/python/example.py", line 125, in send_order
    take_profit=dict(limit_price=str(tp)),
  File "/usr/local/lib/python3.7/site-packages/alpaca_trade_api/rest.py", line 322, in submit_order
    resp = self.post('/orders', params)
  File "/usr/local/lib/python3.7/site-packages/alpaca_trade_api/rest.py", line 165, in post
    return self._request('POST', path, data)
  File "/usr/local/lib/python3.7/site-packages/alpaca_trade_api/rest.py", line 125, in _request
    return self._one_request(method, url, opts, retry)
  File "/usr/local/lib/python3.7/site-packages/alpaca_trade_api/rest.py", line 154, in _one_request
    raise APIError(error, http_error)
alpaca_trade_api.rest.APIError: limit orders require a limit price
2021-02-05 10:16:02,410:ERROR:ORDER NOT SENT
Traceback (most recent call last):
  File "/usr/local/lib/python3.7/site-packages/alpaca_trade_api/rest.py", line 146, in _one_request
    resp.raise_for_status()
  File "/usr/lib/python3.7/site-packages/requests/models.py", line 940, in raise_for_status
    raise HTTPError(http_error_msg, response=self)
requests.exceptions.HTTPError: 422 Client Error: Unprocessable Entity for url: https://paper-api.alpaca.markets/v2/orders

During handling of the above exception, another exception occurred:

Traceback (most recent call last):
  File "/home/will/Documents/Development/Alpaca/python/example.py", line 125, in send_order
    take_profit=dict(limit_price=str(tp)),
  File "/usr/local/lib/python3.7/site-packages/alpaca_trade_api/rest.py", line 322, in submit_order
    resp = self.post('/orders', params)
  File "/usr/local/lib/python3.7/site-packages/alpaca_trade_api/rest.py", line 165, in post
    return self._request('POST', path, data)
  File "/usr/local/lib/python3.7/site-packages/alpaca_trade_api/rest.py", line 125, in _request
    return self._one_request(method, url, opts, retry)
  File "/usr/local/lib/python3.7/site-packages/alpaca_trade_api/rest.py", line 154, in _one_request
    raise APIError(error, http_error)
alpaca_trade_api.rest.APIError: limit orders require a limit price
2021-02-05 10:17:02,632:ERROR:ORDER NOT SENT
Traceback (most recent call last):
  File "/usr/local/lib/python3.7/site-packages/alpaca_trade_api/rest.py", line 146, in _one_request
    resp.raise_for_status()
  File "/usr/lib/python3.7/site-packages/requests/models.py", line 940, in raise_for_status
    raise HTTPError(http_error_msg, response=self)
requests.exceptions.HTTPError: 422 Client Error: Unprocessable Entity for url: https://paper-api.alpaca.markets/v2/orders

During handling of the above exception, another exception occurred:

Traceback (most recent call last):
  File "/home/will/Documents/Development/Alpaca/python/example.py", line 125, in send_order
    take_profit=dict(limit_price=str(tp)),
  File "/usr/local/lib/python3.7/site-packages/alpaca_trade_api/rest.py", line 322, in submit_order
    resp = self.post('/orders', params)
  File "/usr/local/lib/python3.7/site-packages/alpaca_trade_api/rest.py", line 165, in post
    return self._request('POST', path, data)
  File "/usr/local/lib/python3.7/site-packages/alpaca_trade_api/rest.py", line 125, in _request
    return self._one_request(method, url, opts, retry)
  File "/usr/local/lib/python3.7/site-packages/alpaca_trade_api/rest.py", line 154, in _one_request
    raise APIError(error, http_error)
alpaca_trade_api.rest.APIError: limit orders require a limit price
2021-02-05 10:18:02,359:ERROR:ORDER NOT SENT
Traceback (most recent call last):
  File "/usr/local/lib/python3.7/site-packages/alpaca_trade_api/rest.py", line 146, in _one_request
    resp.raise_for_status()
  File "/usr/lib/python3.7/site-packages/requests/models.py", line 940, in raise_for_status
    raise HTTPError(http_error_msg, response=self)
requests.exceptions.HTTPError: 422 Client Error: Unprocessable Entity for url: https://paper-api.alpaca.markets/v2/orders

During handling of the above exception, another exception occurred:

Traceback (most recent call last):
  File "/home/will/Documents/Development/Alpaca/python/example.py", line 125, in send_order
    take_profit=dict(limit_price=str(tp)),
  File "/usr/local/lib/python3.7/site-packages/alpaca_trade_api/rest.py", line 322, in submit_order
    resp = self.post('/orders', params)
  File "/usr/local/lib/python3.7/site-packages/alpaca_trade_api/rest.py", line 165, in post
    return self._request('POST', path, data)
  File "/usr/local/lib/python3.7/site-packages/alpaca_trade_api/rest.py", line 125, in _request
    return self._one_request(method, url, opts, retry)
  File "/usr/local/lib/python3.7/site-packages/alpaca_trade_api/rest.py", line 154, in _one_request
    raise APIError(error, http_error)
alpaca_trade_api.rest.APIError: limit orders require a limit price
2021-02-05 10:19:02,513:ERROR:ORDER NOT SENT
Traceback (most recent call last):
  File "/usr/local/lib/python3.7/site-packages/alpaca_trade_api/rest.py", line 146, in _one_request
    resp.raise_for_status()
  File "/usr/lib/python3.7/site-packages/requests/models.py", line 940, in raise_for_status
    raise HTTPError(http_error_msg, response=self)
requests.exceptions.HTTPError: 422 Client Error: Unprocessable Entity for url: https://paper-api.alpaca.markets/v2/orders

During handling of the above exception, another exception occurred:

Traceback (most recent call last):
  File "/home/will/Documents/Development/Alpaca/python/example.py", line 125, in send_order
    take_profit=dict(limit_price=str(tp)),
  File "/usr/local/lib/python3.7/site-packages/alpaca_trade_api/rest.py", line 322, in submit_order
    resp = self.post('/orders', params)
  File "/usr/local/lib/python3.7/site-packages/alpaca_trade_api/rest.py", line 165, in post
    return self._request('POST', path, data)
  File "/usr/local/lib/python3.7/site-packages/alpaca_trade_api/rest.py", line 125, in _request
    return self._one_request(method, url, opts, retry)
  File "/usr/local/lib/python3.7/site-packages/alpaca_trade_api/rest.py", line 154, in _one_request
    raise APIError(error, http_error)
alpaca_trade_api.rest.APIError: limit orders require a limit price
2021-02-05 10:20:02,520:ERROR:ORDER NOT SENT
Traceback (most recent call last):
  File "/usr/local/lib/python3.7/site-packages/alpaca_trade_api/rest.py", line 146, in _one_request
    resp.raise_for_status()
  File "/usr/lib/python3.7/site-packages/requests/models.py", line 940, in raise_for_status
    raise HTTPError(http_error_msg, response=self)
requests.exceptions.HTTPError: 422 Client Error: Unprocessable Entity for url: https://paper-api.alpaca.markets/v2/orders

During handling of the above exception, another exception occurred:

Traceback (most recent call last):
  File "/home/will/Documents/Development/Alpaca/python/example.py", line 125, in send_order
    take_profit=dict(limit_price=str(tp)),
  File "/usr/local/lib/python3.7/site-packages/alpaca_trade_api/rest.py", line 322, in submit_order
    resp = self.post('/orders', params)
  File "/usr/local/lib/python3.7/site-packages/alpaca_trade_api/rest.py", line 165, in post
    return self._request('POST', path, data)
  File "/usr/local/lib/python3.7/site-packages/alpaca_trade_api/rest.py", line 125, in _request
    return self._one_request(method, url, opts, retry)
  File "/usr/local/lib/python3.7/site-packages/alpaca_trade_api/rest.py", line 154, in _one_request
    raise APIError(error, http_error)
alpaca_trade_api.rest.APIError: limit orders require a limit price
2021-02-05 10:21:02,524:ERROR:ORDER NOT SENT
Traceback (most recent call last):
  File "/usr/local/lib/python3.7/site-packages/alpaca_trade_api/rest.py", line 146, in _one_request
    resp.raise_for_status()
  File "/usr/lib/python3.7/site-packages/requests/models.py", line 940, in raise_for_status
    raise HTTPError(http_error_msg, response=self)
requests.exceptions.HTTPError: 422 Client Error: Unprocessable Entity for url: https://paper-api.alpaca.markets/v2/orders

During handling of the above exception, another exception occurred:

Traceback (most recent call last):
  File "/home/will/Documents/Development/Alpaca/python/example.py", line 125, in send_order
    take_profit=dict(limit_price=str(tp)),
  File "/usr/local/lib/python3.7/site-packages/alpaca_trade_api/rest.py", line 322, in submit_order
    resp = self.post('/orders', params)
  File "/usr/local/lib/python3.7/site-packages/alpaca_trade_api/rest.py", line 165, in post
    return self._request('POST', path, data)
  File "/usr/local/lib/python3.7/site-packages/alpaca_trade_api/rest.py", line 125, in _request
    return self._one_request(method, url, opts, retry)
  File "/usr/local/lib/python3.7/site-packages/alpaca_trade_api/rest.py", line 154, in _one_request
    raise APIError(error, http_error)
alpaca_trade_api.rest.APIError: limit orders require a limit price
2021-02-05 10:22:02,504:ERROR:ORDER NOT SENT
Traceback (most recent call last):
  File "/usr/local/lib/python3.7/site-packages/alpaca_trade_api/rest.py", line 146, in _one_request
    resp.raise_for_status()
  File "/usr/lib/python3.7/site-packages/requests/models.py", line 940, in raise_for_status
    raise HTTPError(http_error_msg, response=self)
requests.exceptions.HTTPError: 422 Client Error: Unprocessable Entity for url: https://paper-api.alpaca.markets/v2/orders

During handling of the above exception, another exception occurred:

Traceback (most recent call last):
  File "/home/will/Documents/Development/Alpaca/python/example.py", line 125, in send_order
    take_profit=dict(limit_price=str(tp)),
  File "/usr/local/lib/python3.7/site-packages/alpaca_trade_api/rest.py", line 322, in submit_order
    resp = self.post('/orders', params)
  File "/usr/local/lib/python3.7/site-packages/alpaca_trade_api/rest.py", line 165, in post
    return self._request('POST', path, data)
  File "/usr/local/lib/python3.7/site-packages/alpaca_trade_api/rest.py", line 125, in _request
    return self._one_request(method, url, opts, retry)
  File "/usr/local/lib/python3.7/site-packages/alpaca_trade_api/rest.py", line 154, in _one_request
    raise APIError(error, http_error)
alpaca_trade_api.rest.APIError: limit orders require a limit price
2021-02-05 10:23:02,516:ERROR:ORDER NOT SENT
Traceback (most recent call last):
  File "/usr/local/lib/python3.7/site-packages/alpaca_trade_api/rest.py", line 146, in _one_request
    resp.raise_for_status()
  File "/usr/lib/python3.7/site-packages/requests/models.py", line 940, in raise_for_status
    raise HTTPError(http_error_msg, response=self)
requests.exceptions.HTTPError: 422 Client Error: Unprocessable Entity for url: https://paper-api.alpaca.markets/v2/orders

During handling of the above exception, another exception occurred:

Traceback (most recent call last):
  File "/home/will/Documents/Development/Alpaca/python/example.py", line 125, in send_order
    take_profit=dict(limit_price=str(tp)),
  File "/usr/local/lib/python3.7/site-packages/alpaca_trade_api/rest.py", line 322, in submit_order
    resp = self.post('/orders', params)
  File "/usr/local/lib/python3.7/site-packages/alpaca_trade_api/rest.py", line 165, in post
    return self._request('POST', path, data)
  File "/usr/local/lib/python3.7/site-packages/alpaca_trade_api/rest.py", line 125, in _request
    return self._one_request(method, url, opts, retry)
  File "/usr/local/lib/python3.7/site-packages/alpaca_trade_api/rest.py", line 154, in _one_request
    raise APIError(error, http_error)
alpaca_trade_api.rest.APIError: limit orders require a limit price
2021-02-05 10:24:02,519:ERROR:ORDER NOT SENT
Traceback (most recent call last):
  File "/usr/local/lib/python3.7/site-packages/alpaca_trade_api/rest.py", line 146, in _one_request
    resp.raise_for_status()
  File "/usr/lib/python3.7/site-packages/requests/models.py", line 940, in raise_for_status
    raise HTTPError(http_error_msg, response=self)
requests.exceptions.HTTPError: 422 Client Error: Unprocessable Entity for url: https://paper-api.alpaca.markets/v2/orders

During handling of the above exception, another exception occurred:

Traceback (most recent call last):
  File "/home/will/Documents/Development/Alpaca/python/example.py", line 125, in send_order
    take_profit=dict(limit_price=str(tp)),
  File "/usr/local/lib/python3.7/site-packages/alpaca_trade_api/rest.py", line 322, in submit_order
    resp = self.post('/orders', params)
  File "/usr/local/lib/python3.7/site-packages/alpaca_trade_api/rest.py", line 165, in post
    return self._request('POST', path, data)
  File "/usr/local/lib/python3.7/site-packages/alpaca_trade_api/rest.py", line 125, in _request
    return self._one_request(method, url, opts, retry)
  File "/usr/local/lib/python3.7/site-packages/alpaca_trade_api/rest.py", line 154, in _one_request
    raise APIError(error, http_error)
alpaca_trade_api.rest.APIError: limit orders require a limit price
2021-02-05 10:25:02,538:ERROR:ORDER NOT SENT
Traceback (most recent call last):
  File "/usr/local/lib/python3.7/site-packages/alpaca_trade_api/rest.py", line 146, in _one_request
    resp.raise_for_status()
  File "/usr/lib/python3.7/site-packages/requests/models.py", line 940, in raise_for_status
    raise HTTPError(http_error_msg, response=self)
requests.exceptions.HTTPError: 422 Client Error: Unprocessable Entity for url: https://paper-api.alpaca.markets/v2/orders

During handling of the above exception, another exception occurred:

Traceback (most recent call last):
  File "/home/will/Documents/Development/Alpaca/python/example.py", line 125, in send_order
    take_profit=dict(limit_price=str(tp)),
  File "/usr/local/lib/python3.7/site-packages/alpaca_trade_api/rest.py", line 322, in submit_order
    resp = self.post('/orders', params)
  File "/usr/local/lib/python3.7/site-packages/alpaca_trade_api/rest.py", line 165, in post
    return self._request('POST', path, data)
  File "/usr/local/lib/python3.7/site-packages/alpaca_trade_api/rest.py", line 125, in _request
    return self._one_request(method, url, opts, retry)
  File "/usr/local/lib/python3.7/site-packages/alpaca_trade_api/rest.py", line 154, in _one_request
    raise APIError(error, http_error)
alpaca_trade_api.rest.APIError: limit orders require a limit price
2021-02-05 10:26:02,438:ERROR:ORDER NOT SENT
Traceback (most recent call last):
  File "/usr/local/lib/python3.7/site-packages/alpaca_trade_api/rest.py", line 146, in _one_request
    resp.raise_for_status()
  File "/usr/lib/python3.7/site-packages/requests/models.py", line 940, in raise_for_status
    raise HTTPError(http_error_msg, response=self)
requests.exceptions.HTTPError: 422 Client Error: Unprocessable Entity for url: https://paper-api.alpaca.markets/v2/orders

During handling of the above exception, another exception occurred:

Traceback (most recent call last):
  File "/home/will/Documents/Development/Alpaca/python/example.py", line 125, in send_order
    take_profit=dict(limit_price=str(tp)),
  File "/usr/local/lib/python3.7/site-packages/alpaca_trade_api/rest.py", line 322, in submit_order
    resp = self.post('/orders', params)
  File "/usr/local/lib/python3.7/site-packages/alpaca_trade_api/rest.py", line 165, in post
    return self._request('POST', path, data)
  File "/usr/local/lib/python3.7/site-packages/alpaca_trade_api/rest.py", line 125, in _request
    return self._one_request(method, url, opts, retry)
  File "/usr/local/lib/python3.7/site-packages/alpaca_trade_api/rest.py", line 154, in _one_request
    raise APIError(error, http_error)
alpaca_trade_api.rest.APIError: limit orders require a limit price
2021-02-05 10:27:02,619:ERROR:ORDER NOT SENT
Traceback (most recent call last):
  File "/usr/local/lib/python3.7/site-packages/alpaca_trade_api/rest.py", line 146, in _one_request
    resp.raise_for_status()
  File "/usr/lib/python3.7/site-packages/requests/models.py", line 940, in raise_for_status
    raise HTTPError(http_error_msg, response=self)
requests.exceptions.HTTPError: 422 Client Error: Unprocessable Entity for url: https://paper-api.alpaca.markets/v2/orders

During handling of the above exception, another exception occurred:

Traceback (most recent call last):
  File "/home/will/Documents/Development/Alpaca/python/example.py", line 125, in send_order
    take_profit=dict(limit_price=str(tp)),
  File "/usr/local/lib/python3.7/site-packages/alpaca_trade_api/rest.py", line 322, in submit_order
    resp = self.post('/orders', params)
  File "/usr/local/lib/python3.7/site-packages/alpaca_trade_api/rest.py", line 165, in post
    return self._request('POST', path, data)
  File "/usr/local/lib/python3.7/site-packages/alpaca_trade_api/rest.py", line 125, in _request
    return self._one_request(method, url, opts, retry)
  File "/usr/local/lib/python3.7/site-packages/alpaca_trade_api/rest.py", line 154, in _one_request
    raise APIError(error, http_error)
alpaca_trade_api.rest.APIError: limit orders require a limit price
2021-02-05 10:28:02,630:ERROR:ORDER NOT SENT
Traceback (most recent call last):
  File "/usr/local/lib/python3.7/site-packages/alpaca_trade_api/rest.py", line 146, in _one_request
    resp.raise_for_status()
  File "/usr/lib/python3.7/site-packages/requests/models.py", line 940, in raise_for_status
    raise HTTPError(http_error_msg, response=self)
requests.exceptions.HTTPError: 422 Client Error: Unprocessable Entity for url: https://paper-api.alpaca.markets/v2/orders

During handling of the above exception, another exception occurred:

Traceback (most recent call last):
  File "/home/will/Documents/Development/Alpaca/python/example.py", line 125, in send_order
    take_profit=dict(limit_price=str(tp)),
  File "/usr/local/lib/python3.7/site-packages/alpaca_trade_api/rest.py", line 322, in submit_order
    resp = self.post('/orders', params)
  File "/usr/local/lib/python3.7/site-packages/alpaca_trade_api/rest.py", line 165, in post
    return self._request('POST', path, data)
  File "/usr/local/lib/python3.7/site-packages/alpaca_trade_api/rest.py", line 125, in _request
    return self._one_request(method, url, opts, retry)
  File "/usr/local/lib/python3.7/site-packages/alpaca_trade_api/rest.py", line 154, in _one_request
    raise APIError(error, http_error)
alpaca_trade_api.rest.APIError: limit orders require a limit price
2021-02-05 10:29:02,446:ERROR:ORDER NOT SENT
Traceback (most recent call last):
  File "/usr/local/lib/python3.7/site-packages/alpaca_trade_api/rest.py", line 146, in _one_request
    resp.raise_for_status()
  File "/usr/lib/python3.7/site-packages/requests/models.py", line 940, in raise_for_status
    raise HTTPError(http_error_msg, response=self)
requests.exceptions.HTTPError: 422 Client Error: Unprocessable Entity for url: https://paper-api.alpaca.markets/v2/orders

During handling of the above exception, another exception occurred:

Traceback (most recent call last):
  File "/home/will/Documents/Development/Alpaca/python/example.py", line 125, in send_order
    take_profit=dict(limit_price=str(tp)),
  File "/usr/local/lib/python3.7/site-packages/alpaca_trade_api/rest.py", line 322, in submit_order
    resp = self.post('/orders', params)
  File "/usr/local/lib/python3.7/site-packages/alpaca_trade_api/rest.py", line 165, in post
    return self._request('POST', path, data)
  File "/usr/local/lib/python3.7/site-packages/alpaca_trade_api/rest.py", line 125, in _request
    return self._one_request(method, url, opts, retry)
  File "/usr/local/lib/python3.7/site-packages/alpaca_trade_api/rest.py", line 154, in _one_request
    raise APIError(error, http_error)
alpaca_trade_api.rest.APIError: limit orders require a limit price
2021-02-05 10:30:02,382:ERROR:ORDER NOT SENT
Traceback (most recent call last):
  File "/usr/local/lib/python3.7/site-packages/alpaca_trade_api/rest.py", line 146, in _one_request
    resp.raise_for_status()
  File "/usr/lib/python3.7/site-packages/requests/models.py", line 940, in raise_for_status
    raise HTTPError(http_error_msg, response=self)
requests.exceptions.HTTPError: 422 Client Error: Unprocessable Entity for url: https://paper-api.alpaca.markets/v2/orders

During handling of the above exception, another exception occurred:

Traceback (most recent call last):
  File "/home/will/Documents/Development/Alpaca/python/example.py", line 125, in send_order
    take_profit=dict(limit_price=str(tp)),
  File "/usr/local/lib/python3.7/site-packages/alpaca_trade_api/rest.py", line 322, in submit_order
    resp = self.post('/orders', params)
  File "/usr/local/lib/python3.7/site-packages/alpaca_trade_api/rest.py", line 165, in post
    return self._request('POST', path, data)
  File "/usr/local/lib/python3.7/site-packages/alpaca_trade_api/rest.py", line 125, in _request
    return self._one_request(method, url, opts, retry)
  File "/usr/local/lib/python3.7/site-packages/alpaca_trade_api/rest.py", line 154, in _one_request
    raise APIError(error, http_error)
alpaca_trade_api.rest.APIError: limit orders require a limit price
2021-02-05 10:31:02,656:ERROR:ORDER NOT SENT
Traceback (most recent call last):
  File "/usr/local/lib/python3.7/site-packages/alpaca_trade_api/rest.py", line 146, in _one_request
    resp.raise_for_status()
  File "/usr/lib/python3.7/site-packages/requests/models.py", line 940, in raise_for_status
    raise HTTPError(http_error_msg, response=self)
requests.exceptions.HTTPError: 422 Client Error: Unprocessable Entity for url: https://paper-api.alpaca.markets/v2/orders

During handling of the above exception, another exception occurred:

Traceback (most recent call last):
  File "/home/will/Documents/Development/Alpaca/python/example.py", line 125, in send_order
    take_profit=dict(limit_price=str(tp)),
  File "/usr/local/lib/python3.7/site-packages/alpaca_trade_api/rest.py", line 322, in submit_order
    resp = self.post('/orders', params)
  File "/usr/local/lib/python3.7/site-packages/alpaca_trade_api/rest.py", line 165, in post
    return self._request('POST', path, data)
  File "/usr/local/lib/python3.7/site-packages/alpaca_trade_api/rest.py", line 125, in _request
    return self._one_request(method, url, opts, retry)
  File "/usr/local/lib/python3.7/site-packages/alpaca_trade_api/rest.py", line 154, in _one_request
    raise APIError(error, http_error)
alpaca_trade_api.rest.APIError: limit orders require a limit price
2021-02-05 10:32:02,883:ERROR:ORDER NOT SENT
Traceback (most recent call last):
  File "/usr/local/lib/python3.7/site-packages/alpaca_trade_api/rest.py", line 146, in _one_request
    resp.raise_for_status()
  File "/usr/lib/python3.7/site-packages/requests/models.py", line 940, in raise_for_status
    raise HTTPError(http_error_msg, response=self)
requests.exceptions.HTTPError: 422 Client Error: Unprocessable Entity for url: https://paper-api.alpaca.markets/v2/orders

During handling of the above exception, another exception occurred:

Traceback (most recent call last):
  File "/home/will/Documents/Development/Alpaca/python/example.py", line 125, in send_order
    take_profit=dict(limit_price=str(tp)),
  File "/usr/local/lib/python3.7/site-packages/alpaca_trade_api/rest.py", line 322, in submit_order
    resp = self.post('/orders', params)
  File "/usr/local/lib/python3.7/site-packages/alpaca_trade_api/rest.py", line 165, in post
    return self._request('POST', path, data)
  File "/usr/local/lib/python3.7/site-packages/alpaca_trade_api/rest.py", line 125, in _request
    return self._one_request(method, url, opts, retry)
  File "/usr/local/lib/python3.7/site-packages/alpaca_trade_api/rest.py", line 154, in _one_request
    raise APIError(error, http_error)
alpaca_trade_api.rest.APIError: limit orders require a limit price
2021-02-05 10:33:02,253:ERROR:ORDER NOT SENT
Traceback (most recent call last):
  File "/usr/local/lib/python3.7/site-packages/alpaca_trade_api/rest.py", line 146, in _one_request
    resp.raise_for_status()
  File "/usr/lib/python3.7/site-packages/requests/models.py", line 940, in raise_for_status
    raise HTTPError(http_error_msg, response=self)
requests.exceptions.HTTPError: 422 Client Error: Unprocessable Entity for url: https://paper-api.alpaca.markets/v2/orders

During handling of the above exception, another exception occurred:

Traceback (most recent call last):
  File "/home/will/Documents/Development/Alpaca/python/example.py", line 125, in send_order
    take_profit=dict(limit_price=str(tp)),
  File "/usr/local/lib/python3.7/site-packages/alpaca_trade_api/rest.py", line 322, in submit_order
    resp = self.post('/orders', params)
  File "/usr/local/lib/python3.7/site-packages/alpaca_trade_api/rest.py", line 165, in post
    return self._request('POST', path, data)
  File "/usr/local/lib/python3.7/site-packages/alpaca_trade_api/rest.py", line 125, in _request
    return self._one_request(method, url, opts, retry)
  File "/usr/local/lib/python3.7/site-packages/alpaca_trade_api/rest.py", line 154, in _one_request
    raise APIError(error, http_error)
alpaca_trade_api.rest.APIError: limit orders require a limit price
2021-02-05 10:34:02,345:ERROR:ORDER NOT SENT
Traceback (most recent call last):
  File "/usr/local/lib/python3.7/site-packages/alpaca_trade_api/rest.py", line 146, in _one_request
    resp.raise_for_status()
  File "/usr/lib/python3.7/site-packages/requests/models.py", line 940, in raise_for_status
    raise HTTPError(http_error_msg, response=self)
requests.exceptions.HTTPError: 422 Client Error: Unprocessable Entity for url: https://paper-api.alpaca.markets/v2/orders

During handling of the above exception, another exception occurred:

Traceback (most recent call last):
  File "/home/will/Documents/Development/Alpaca/python/example.py", line 125, in send_order
    take_profit=dict(limit_price=str(tp)),
  File "/usr/local/lib/python3.7/site-packages/alpaca_trade_api/rest.py", line 322, in submit_order
    resp = self.post('/orders', params)
  File "/usr/local/lib/python3.7/site-packages/alpaca_trade_api/rest.py", line 165, in post
    return self._request('POST', path, data)
  File "/usr/local/lib/python3.7/site-packages/alpaca_trade_api/rest.py", line 125, in _request
    return self._one_request(method, url, opts, retry)
  File "/usr/local/lib/python3.7/site-packages/alpaca_trade_api/rest.py", line 154, in _one_request
    raise APIError(error, http_error)
alpaca_trade_api.rest.APIError: limit orders require a limit price
2021-02-05 10:35:02,382:ERROR:ORDER NOT SENT
Traceback (most recent call last):
  File "/usr/local/lib/python3.7/site-packages/alpaca_trade_api/rest.py", line 146, in _one_request
    resp.raise_for_status()
  File "/usr/lib/python3.7/site-packages/requests/models.py", line 940, in raise_for_status
    raise HTTPError(http_error_msg, response=self)
requests.exceptions.HTTPError: 422 Client Error: Unprocessable Entity for url: https://paper-api.alpaca.markets/v2/orders

During handling of the above exception, another exception occurred:

Traceback (most recent call last):
  File "/home/will/Documents/Development/Alpaca/python/example.py", line 125, in send_order
    take_profit=dict(limit_price=str(tp)),
  File "/usr/local/lib/python3.7/site-packages/alpaca_trade_api/rest.py", line 322, in submit_order
    resp = self.post('/orders', params)
  File "/usr/local/lib/python3.7/site-packages/alpaca_trade_api/rest.py", line 165, in post
    return self._request('POST', path, data)
  File "/usr/local/lib/python3.7/site-packages/alpaca_trade_api/rest.py", line 125, in _request
    return self._one_request(method, url, opts, retry)
  File "/usr/local/lib/python3.7/site-packages/alpaca_trade_api/rest.py", line 154, in _one_request
    raise APIError(error, http_error)
alpaca_trade_api.rest.APIError: limit orders require a limit price
2021-02-05 10:36:02,361:ERROR:ORDER NOT SENT
Traceback (most recent call last):
  File "/usr/local/lib/python3.7/site-packages/alpaca_trade_api/rest.py", line 146, in _one_request
    resp.raise_for_status()
  File "/usr/lib/python3.7/site-packages/requests/models.py", line 940, in raise_for_status
    raise HTTPError(http_error_msg, response=self)
requests.exceptions.HTTPError: 422 Client Error: Unprocessable Entity for url: https://paper-api.alpaca.markets/v2/orders

During handling of the above exception, another exception occurred:

Traceback (most recent call last):
  File "/home/will/Documents/Development/Alpaca/python/example.py", line 125, in send_order
    take_profit=dict(limit_price=str(tp)),
  File "/usr/local/lib/python3.7/site-packages/alpaca_trade_api/rest.py", line 322, in submit_order
    resp = self.post('/orders', params)
  File "/usr/local/lib/python3.7/site-packages/alpaca_trade_api/rest.py", line 165, in post
    return self._request('POST', path, data)
  File "/usr/local/lib/python3.7/site-packages/alpaca_trade_api/rest.py", line 125, in _request
    return self._one_request(method, url, opts, retry)
  File "/usr/local/lib/python3.7/site-packages/alpaca_trade_api/rest.py", line 154, in _one_request
    raise APIError(error, http_error)
alpaca_trade_api.rest.APIError: limit orders require a limit price
2021-02-05 10:37:02,569:ERROR:ORDER NOT SENT
Traceback (most recent call last):
  File "/usr/local/lib/python3.7/site-packages/alpaca_trade_api/rest.py", line 146, in _one_request
    resp.raise_for_status()
  File "/usr/lib/python3.7/site-packages/requests/models.py", line 940, in raise_for_status
    raise HTTPError(http_error_msg, response=self)
requests.exceptions.HTTPError: 422 Client Error: Unprocessable Entity for url: https://paper-api.alpaca.markets/v2/orders

During handling of the above exception, another exception occurred:

Traceback (most recent call last):
  File "/home/will/Documents/Development/Alpaca/python/example.py", line 125, in send_order
    take_profit=dict(limit_price=str(tp)),
  File "/usr/local/lib/python3.7/site-packages/alpaca_trade_api/rest.py", line 322, in submit_order
    resp = self.post('/orders', params)
  File "/usr/local/lib/python3.7/site-packages/alpaca_trade_api/rest.py", line 165, in post
    return self._request('POST', path, data)
  File "/usr/local/lib/python3.7/site-packages/alpaca_trade_api/rest.py", line 125, in _request
    return self._one_request(method, url, opts, retry)
  File "/usr/local/lib/python3.7/site-packages/alpaca_trade_api/rest.py", line 154, in _one_request
    raise APIError(error, http_error)
alpaca_trade_api.rest.APIError: limit orders require a limit price
2021-02-05 10:38:02,424:ERROR:ORDER NOT SENT
Traceback (most recent call last):
  File "/usr/local/lib/python3.7/site-packages/alpaca_trade_api/rest.py", line 146, in _one_request
    resp.raise_for_status()
  File "/usr/lib/python3.7/site-packages/requests/models.py", line 940, in raise_for_status
    raise HTTPError(http_error_msg, response=self)
requests.exceptions.HTTPError: 422 Client Error: Unprocessable Entity for url: https://paper-api.alpaca.markets/v2/orders

During handling of the above exception, another exception occurred:

Traceback (most recent call last):
  File "/home/will/Documents/Development/Alpaca/python/example.py", line 125, in send_order
    take_profit=dict(limit_price=str(tp)),
  File "/usr/local/lib/python3.7/site-packages/alpaca_trade_api/rest.py", line 322, in submit_order
    resp = self.post('/orders', params)
  File "/usr/local/lib/python3.7/site-packages/alpaca_trade_api/rest.py", line 165, in post
    return self._request('POST', path, data)
  File "/usr/local/lib/python3.7/site-packages/alpaca_trade_api/rest.py", line 125, in _request
    return self._one_request(method, url, opts, retry)
  File "/usr/local/lib/python3.7/site-packages/alpaca_trade_api/rest.py", line 154, in _one_request
    raise APIError(error, http_error)
alpaca_trade_api.rest.APIError: limit orders require a limit price
2021-02-05 10:39:02,409:ERROR:ORDER NOT SENT
Traceback (most recent call last):
  File "/usr/local/lib/python3.7/site-packages/alpaca_trade_api/rest.py", line 146, in _one_request
    resp.raise_for_status()
  File "/usr/lib/python3.7/site-packages/requests/models.py", line 940, in raise_for_status
    raise HTTPError(http_error_msg, response=self)
requests.exceptions.HTTPError: 422 Client Error: Unprocessable Entity for url: https://paper-api.alpaca.markets/v2/orders

During handling of the above exception, another exception occurred:

Traceback (most recent call last):
  File "/home/will/Documents/Development/Alpaca/python/example.py", line 125, in send_order
    take_profit=dict(limit_price=str(tp)),
  File "/usr/local/lib/python3.7/site-packages/alpaca_trade_api/rest.py", line 322, in submit_order
    resp = self.post('/orders', params)
  File "/usr/local/lib/python3.7/site-packages/alpaca_trade_api/rest.py", line 165, in post
    return self._request('POST', path, data)
  File "/usr/local/lib/python3.7/site-packages/alpaca_trade_api/rest.py", line 125, in _request
    return self._one_request(method, url, opts, retry)
  File "/usr/local/lib/python3.7/site-packages/alpaca_trade_api/rest.py", line 154, in _one_request
    raise APIError(error, http_error)
alpaca_trade_api.rest.APIError: limit orders require a limit price
2021-02-05 10:40:02,511:ERROR:ORDER NOT SENT
Traceback (most recent call last):
  File "/usr/local/lib/python3.7/site-packages/alpaca_trade_api/rest.py", line 146, in _one_request
    resp.raise_for_status()
  File "/usr/lib/python3.7/site-packages/requests/models.py", line 940, in raise_for_status
    raise HTTPError(http_error_msg, response=self)
requests.exceptions.HTTPError: 422 Client Error: Unprocessable Entity for url: https://paper-api.alpaca.markets/v2/orders

During handling of the above exception, another exception occurred:

Traceback (most recent call last):
  File "/home/will/Documents/Development/Alpaca/python/example.py", line 125, in send_order
    take_profit=dict(limit_price=str(tp)),
  File "/usr/local/lib/python3.7/site-packages/alpaca_trade_api/rest.py", line 322, in submit_order
    resp = self.post('/orders', params)
  File "/usr/local/lib/python3.7/site-packages/alpaca_trade_api/rest.py", line 165, in post
    return self._request('POST', path, data)
  File "/usr/local/lib/python3.7/site-packages/alpaca_trade_api/rest.py", line 125, in _request
    return self._one_request(method, url, opts, retry)
  File "/usr/local/lib/python3.7/site-packages/alpaca_trade_api/rest.py", line 154, in _one_request
    raise APIError(error, http_error)
alpaca_trade_api.rest.APIError: limit orders require a limit price
2021-02-05 10:41:02,382:ERROR:ORDER NOT SENT
Traceback (most recent call last):
  File "/usr/local/lib/python3.7/site-packages/alpaca_trade_api/rest.py", line 146, in _one_request
    resp.raise_for_status()
  File "/usr/lib/python3.7/site-packages/requests/models.py", line 940, in raise_for_status
    raise HTTPError(http_error_msg, response=self)
requests.exceptions.HTTPError: 422 Client Error: Unprocessable Entity for url: https://paper-api.alpaca.markets/v2/orders

During handling of the above exception, another exception occurred:

Traceback (most recent call last):
  File "/home/will/Documents/Development/Alpaca/python/example.py", line 125, in send_order
    take_profit=dict(limit_price=str(tp)),
  File "/usr/local/lib/python3.7/site-packages/alpaca_trade_api/rest.py", line 322, in submit_order
    resp = self.post('/orders', params)
  File "/usr/local/lib/python3.7/site-packages/alpaca_trade_api/rest.py", line 165, in post
    return self._request('POST', path, data)
  File "/usr/local/lib/python3.7/site-packages/alpaca_trade_api/rest.py", line 125, in _request
    return self._one_request(method, url, opts, retry)
  File "/usr/local/lib/python3.7/site-packages/alpaca_trade_api/rest.py", line 154, in _one_request
    raise APIError(error, http_error)
alpaca_trade_api.rest.APIError: limit orders require a limit price
2021-02-05 10:42:02,333:ERROR:ORDER NOT SENT
Traceback (most recent call last):
  File "/usr/local/lib/python3.7/site-packages/alpaca_trade_api/rest.py", line 146, in _one_request
    resp.raise_for_status()
  File "/usr/lib/python3.7/site-packages/requests/models.py", line 940, in raise_for_status
    raise HTTPError(http_error_msg, response=self)
requests.exceptions.HTTPError: 422 Client Error: Unprocessable Entity for url: https://paper-api.alpaca.markets/v2/orders

During handling of the above exception, another exception occurred:

Traceback (most recent call last):
  File "/home/will/Documents/Development/Alpaca/python/example.py", line 125, in send_order
    take_profit=dict(limit_price=str(tp)),
  File "/usr/local/lib/python3.7/site-packages/alpaca_trade_api/rest.py", line 322, in submit_order
    resp = self.post('/orders', params)
  File "/usr/local/lib/python3.7/site-packages/alpaca_trade_api/rest.py", line 165, in post
    return self._request('POST', path, data)
  File "/usr/local/lib/python3.7/site-packages/alpaca_trade_api/rest.py", line 125, in _request
    return self._one_request(method, url, opts, retry)
  File "/usr/local/lib/python3.7/site-packages/alpaca_trade_api/rest.py", line 154, in _one_request
    raise APIError(error, http_error)
alpaca_trade_api.rest.APIError: limit orders require a limit price
2021-02-05 10:43:02,338:ERROR:ORDER NOT SENT
Traceback (most recent call last):
  File "/usr/local/lib/python3.7/site-packages/alpaca_trade_api/rest.py", line 146, in _one_request
    resp.raise_for_status()
  File "/usr/lib/python3.7/site-packages/requests/models.py", line 940, in raise_for_status
    raise HTTPError(http_error_msg, response=self)
requests.exceptions.HTTPError: 422 Client Error: Unprocessable Entity for url: https://paper-api.alpaca.markets/v2/orders

During handling of the above exception, another exception occurred:

Traceback (most recent call last):
  File "/home/will/Documents/Development/Alpaca/python/example.py", line 125, in send_order
    take_profit=dict(limit_price=str(tp)),
  File "/usr/local/lib/python3.7/site-packages/alpaca_trade_api/rest.py", line 322, in submit_order
    resp = self.post('/orders', params)
  File "/usr/local/lib/python3.7/site-packages/alpaca_trade_api/rest.py", line 165, in post
    return self._request('POST', path, data)
  File "/usr/local/lib/python3.7/site-packages/alpaca_trade_api/rest.py", line 125, in _request
    return self._one_request(method, url, opts, retry)
  File "/usr/local/lib/python3.7/site-packages/alpaca_trade_api/rest.py", line 154, in _one_request
    raise APIError(error, http_error)
alpaca_trade_api.rest.APIError: limit orders require a limit price
2021-02-05 10:44:02,344:ERROR:ORDER NOT SENT
Traceback (most recent call last):
  File "/usr/local/lib/python3.7/site-packages/alpaca_trade_api/rest.py", line 146, in _one_request
    resp.raise_for_status()
  File "/usr/lib/python3.7/site-packages/requests/models.py", line 940, in raise_for_status
    raise HTTPError(http_error_msg, response=self)
requests.exceptions.HTTPError: 422 Client Error: Unprocessable Entity for url: https://paper-api.alpaca.markets/v2/orders

During handling of the above exception, another exception occurred:

Traceback (most recent call last):
  File "/home/will/Documents/Development/Alpaca/python/example.py", line 125, in send_order
    take_profit=dict(limit_price=str(tp)),
  File "/usr/local/lib/python3.7/site-packages/alpaca_trade_api/rest.py", line 322, in submit_order
    resp = self.post('/orders', params)
  File "/usr/local/lib/python3.7/site-packages/alpaca_trade_api/rest.py", line 165, in post
    return self._request('POST', path, data)
  File "/usr/local/lib/python3.7/site-packages/alpaca_trade_api/rest.py", line 125, in _request
    return self._one_request(method, url, opts, retry)
  File "/usr/local/lib/python3.7/site-packages/alpaca_trade_api/rest.py", line 154, in _one_request
    raise APIError(error, http_error)
alpaca_trade_api.rest.APIError: limit orders require a limit price
2021-02-05 10:45:02,424:ERROR:ORDER NOT SENT
Traceback (most recent call last):
  File "/usr/local/lib/python3.7/site-packages/alpaca_trade_api/rest.py", line 146, in _one_request
    resp.raise_for_status()
  File "/usr/lib/python3.7/site-packages/requests/models.py", line 940, in raise_for_status
    raise HTTPError(http_error_msg, response=self)
requests.exceptions.HTTPError: 422 Client Error: Unprocessable Entity for url: https://paper-api.alpaca.markets/v2/orders

During handling of the above exception, another exception occurred:

Traceback (most recent call last):
  File "/home/will/Documents/Development/Alpaca/python/example.py", line 125, in send_order
    take_profit=dict(limit_price=str(tp)),
  File "/usr/local/lib/python3.7/site-packages/alpaca_trade_api/rest.py", line 322, in submit_order
    resp = self.post('/orders', params)
  File "/usr/local/lib/python3.7/site-packages/alpaca_trade_api/rest.py", line 165, in post
    return self._request('POST', path, data)
  File "/usr/local/lib/python3.7/site-packages/alpaca_trade_api/rest.py", line 125, in _request
    return self._one_request(method, url, opts, retry)
  File "/usr/local/lib/python3.7/site-packages/alpaca_trade_api/rest.py", line 154, in _one_request
    raise APIError(error, http_error)
alpaca_trade_api.rest.APIError: limit orders require a limit price
2021-02-05 10:46:02,531:ERROR:ORDER NOT SENT
Traceback (most recent call last):
  File "/usr/local/lib/python3.7/site-packages/alpaca_trade_api/rest.py", line 146, in _one_request
    resp.raise_for_status()
  File "/usr/lib/python3.7/site-packages/requests/models.py", line 940, in raise_for_status
    raise HTTPError(http_error_msg, response=self)
requests.exceptions.HTTPError: 422 Client Error: Unprocessable Entity for url: https://paper-api.alpaca.markets/v2/orders

During handling of the above exception, another exception occurred:

Traceback (most recent call last):
  File "/home/will/Documents/Development/Alpaca/python/example.py", line 125, in send_order
    take_profit=dict(limit_price=str(tp)),
  File "/usr/local/lib/python3.7/site-packages/alpaca_trade_api/rest.py", line 322, in submit_order
    resp = self.post('/orders', params)
  File "/usr/local/lib/python3.7/site-packages/alpaca_trade_api/rest.py", line 165, in post
    return self._request('POST', path, data)
  File "/usr/local/lib/python3.7/site-packages/alpaca_trade_api/rest.py", line 125, in _request
    return self._one_request(method, url, opts, retry)
  File "/usr/local/lib/python3.7/site-packages/alpaca_trade_api/rest.py", line 154, in _one_request
    raise APIError(error, http_error)
alpaca_trade_api.rest.APIError: limit orders require a limit price
2021-02-05 10:47:02,420:ERROR:ORDER NOT SENT
Traceback (most recent call last):
  File "/usr/local/lib/python3.7/site-packages/alpaca_trade_api/rest.py", line 146, in _one_request
    resp.raise_for_status()
  File "/usr/lib/python3.7/site-packages/requests/models.py", line 940, in raise_for_status
    raise HTTPError(http_error_msg, response=self)
requests.exceptions.HTTPError: 422 Client Error: Unprocessable Entity for url: https://paper-api.alpaca.markets/v2/orders

During handling of the above exception, another exception occurred:

Traceback (most recent call last):
  File "/home/will/Documents/Development/Alpaca/python/example.py", line 125, in send_order
    take_profit=dict(limit_price=str(tp)),
  File "/usr/local/lib/python3.7/site-packages/alpaca_trade_api/rest.py", line 322, in submit_order
    resp = self.post('/orders', params)
  File "/usr/local/lib/python3.7/site-packages/alpaca_trade_api/rest.py", line 165, in post
    return self._request('POST', path, data)
  File "/usr/local/lib/python3.7/site-packages/alpaca_trade_api/rest.py", line 125, in _request
    return self._one_request(method, url, opts, retry)
  File "/usr/local/lib/python3.7/site-packages/alpaca_trade_api/rest.py", line 154, in _one_request
    raise APIError(error, http_error)
alpaca_trade_api.rest.APIError: limit orders require a limit price
2021-02-05 10:48:02,536:ERROR:ORDER NOT SENT
Traceback (most recent call last):
  File "/usr/local/lib/python3.7/site-packages/alpaca_trade_api/rest.py", line 146, in _one_request
    resp.raise_for_status()
  File "/usr/lib/python3.7/site-packages/requests/models.py", line 940, in raise_for_status
    raise HTTPError(http_error_msg, response=self)
requests.exceptions.HTTPError: 422 Client Error: Unprocessable Entity for url: https://paper-api.alpaca.markets/v2/orders

During handling of the above exception, another exception occurred:

Traceback (most recent call last):
  File "/home/will/Documents/Development/Alpaca/python/example.py", line 125, in send_order
    take_profit=dict(limit_price=str(tp)),
  File "/usr/local/lib/python3.7/site-packages/alpaca_trade_api/rest.py", line 322, in submit_order
    resp = self.post('/orders', params)
  File "/usr/local/lib/python3.7/site-packages/alpaca_trade_api/rest.py", line 165, in post
    return self._request('POST', path, data)
  File "/usr/local/lib/python3.7/site-packages/alpaca_trade_api/rest.py", line 125, in _request
    return self._one_request(method, url, opts, retry)
  File "/usr/local/lib/python3.7/site-packages/alpaca_trade_api/rest.py", line 154, in _one_request
    raise APIError(error, http_error)
alpaca_trade_api.rest.APIError: limit orders require a limit price
2021-02-05 10:49:02,360:ERROR:ORDER NOT SENT
Traceback (most recent call last):
  File "/usr/local/lib/python3.7/site-packages/alpaca_trade_api/rest.py", line 146, in _one_request
    resp.raise_for_status()
  File "/usr/lib/python3.7/site-packages/requests/models.py", line 940, in raise_for_status
    raise HTTPError(http_error_msg, response=self)
requests.exceptions.HTTPError: 422 Client Error: Unprocessable Entity for url: https://paper-api.alpaca.markets/v2/orders

During handling of the above exception, another exception occurred:

Traceback (most recent call last):
  File "/home/will/Documents/Development/Alpaca/python/example.py", line 125, in send_order
    take_profit=dict(limit_price=str(tp)),
  File "/usr/local/lib/python3.7/site-packages/alpaca_trade_api/rest.py", line 322, in submit_order
    resp = self.post('/orders', params)
  File "/usr/local/lib/python3.7/site-packages/alpaca_trade_api/rest.py", line 165, in post
    return self._request('POST', path, data)
  File "/usr/local/lib/python3.7/site-packages/alpaca_trade_api/rest.py", line 125, in _request
    return self._one_request(method, url, opts, retry)
  File "/usr/local/lib/python3.7/site-packages/alpaca_trade_api/rest.py", line 154, in _one_request
    raise APIError(error, http_error)
alpaca_trade_api.rest.APIError: limit orders require a limit price
2021-02-05 10:50:02,640:ERROR:ORDER NOT SENT
Traceback (most recent call last):
  File "/usr/local/lib/python3.7/site-packages/alpaca_trade_api/rest.py", line 146, in _one_request
    resp.raise_for_status()
  File "/usr/lib/python3.7/site-packages/requests/models.py", line 940, in raise_for_status
    raise HTTPError(http_error_msg, response=self)
requests.exceptions.HTTPError: 422 Client Error: Unprocessable Entity for url: https://paper-api.alpaca.markets/v2/orders

During handling of the above exception, another exception occurred:

Traceback (most recent call last):
  File "/home/will/Documents/Development/Alpaca/python/example.py", line 125, in send_order
    take_profit=dict(limit_price=str(tp)),
  File "/usr/local/lib/python3.7/site-packages/alpaca_trade_api/rest.py", line 322, in submit_order
    resp = self.post('/orders', params)
  File "/usr/local/lib/python3.7/site-packages/alpaca_trade_api/rest.py", line 165, in post
    return self._request('POST', path, data)
  File "/usr/local/lib/python3.7/site-packages/alpaca_trade_api/rest.py", line 125, in _request
    return self._one_request(method, url, opts, retry)
  File "/usr/local/lib/python3.7/site-packages/alpaca_trade_api/rest.py", line 154, in _one_request
    raise APIError(error, http_error)
alpaca_trade_api.rest.APIError: limit orders require a limit price
2021-02-05 10:51:02,450:ERROR:ORDER NOT SENT
Traceback (most recent call last):
  File "/usr/local/lib/python3.7/site-packages/alpaca_trade_api/rest.py", line 146, in _one_request
    resp.raise_for_status()
  File "/usr/lib/python3.7/site-packages/requests/models.py", line 940, in raise_for_status
    raise HTTPError(http_error_msg, response=self)
requests.exceptions.HTTPError: 422 Client Error: Unprocessable Entity for url: https://paper-api.alpaca.markets/v2/orders

During handling of the above exception, another exception occurred:

Traceback (most recent call last):
  File "/home/will/Documents/Development/Alpaca/python/example.py", line 125, in send_order
    take_profit=dict(limit_price=str(tp)),
  File "/usr/local/lib/python3.7/site-packages/alpaca_trade_api/rest.py", line 322, in submit_order
    resp = self.post('/orders', params)
  File "/usr/local/lib/python3.7/site-packages/alpaca_trade_api/rest.py", line 165, in post
    return self._request('POST', path, data)
  File "/usr/local/lib/python3.7/site-packages/alpaca_trade_api/rest.py", line 125, in _request
    return self._one_request(method, url, opts, retry)
  File "/usr/local/lib/python3.7/site-packages/alpaca_trade_api/rest.py", line 154, in _one_request
    raise APIError(error, http_error)
alpaca_trade_api.rest.APIError: limit orders require a limit price
2021-02-05 10:52:02,383:ERROR:ORDER NOT SENT
Traceback (most recent call last):
  File "/usr/local/lib/python3.7/site-packages/alpaca_trade_api/rest.py", line 146, in _one_request
    resp.raise_for_status()
  File "/usr/lib/python3.7/site-packages/requests/models.py", line 940, in raise_for_status
    raise HTTPError(http_error_msg, response=self)
requests.exceptions.HTTPError: 422 Client Error: Unprocessable Entity for url: https://paper-api.alpaca.markets/v2/orders

During handling of the above exception, another exception occurred:

Traceback (most recent call last):
  File "/home/will/Documents/Development/Alpaca/python/example.py", line 125, in send_order
    take_profit=dict(limit_price=str(tp)),
  File "/usr/local/lib/python3.7/site-packages/alpaca_trade_api/rest.py", line 322, in submit_order
    resp = self.post('/orders', params)
  File "/usr/local/lib/python3.7/site-packages/alpaca_trade_api/rest.py", line 165, in post
    return self._request('POST', path, data)
  File "/usr/local/lib/python3.7/site-packages/alpaca_trade_api/rest.py", line 125, in _request
    return self._one_request(method, url, opts, retry)
  File "/usr/local/lib/python3.7/site-packages/alpaca_trade_api/rest.py", line 154, in _one_request
    raise APIError(error, http_error)
alpaca_trade_api.rest.APIError: limit orders require a limit price
2021-02-05 10:53:02,395:ERROR:ORDER NOT SENT
Traceback (most recent call last):
  File "/usr/local/lib/python3.7/site-packages/alpaca_trade_api/rest.py", line 146, in _one_request
    resp.raise_for_status()
  File "/usr/lib/python3.7/site-packages/requests/models.py", line 940, in raise_for_status
    raise HTTPError(http_error_msg, response=self)
requests.exceptions.HTTPError: 422 Client Error: Unprocessable Entity for url: https://paper-api.alpaca.markets/v2/orders

During handling of the above exception, another exception occurred:

Traceback (most recent call last):
  File "/home/will/Documents/Development/Alpaca/python/example.py", line 125, in send_order
    take_profit=dict(limit_price=str(tp)),
  File "/usr/local/lib/python3.7/site-packages/alpaca_trade_api/rest.py", line 322, in submit_order
    resp = self.post('/orders', params)
  File "/usr/local/lib/python3.7/site-packages/alpaca_trade_api/rest.py", line 165, in post
    return self._request('POST', path, data)
  File "/usr/local/lib/python3.7/site-packages/alpaca_trade_api/rest.py", line 125, in _request
    return self._one_request(method, url, opts, retry)
  File "/usr/local/lib/python3.7/site-packages/alpaca_trade_api/rest.py", line 154, in _one_request
    raise APIError(error, http_error)
alpaca_trade_api.rest.APIError: limit orders require a limit price
2021-02-05 10:54:02,492:ERROR:ORDER NOT SENT
Traceback (most recent call last):
  File "/usr/local/lib/python3.7/site-packages/alpaca_trade_api/rest.py", line 146, in _one_request
    resp.raise_for_status()
  File "/usr/lib/python3.7/site-packages/requests/models.py", line 940, in raise_for_status
    raise HTTPError(http_error_msg, response=self)
requests.exceptions.HTTPError: 422 Client Error: Unprocessable Entity for url: https://paper-api.alpaca.markets/v2/orders

During handling of the above exception, another exception occurred:

Traceback (most recent call last):
  File "/home/will/Documents/Development/Alpaca/python/example.py", line 125, in send_order
    take_profit=dict(limit_price=str(tp)),
  File "/usr/local/lib/python3.7/site-packages/alpaca_trade_api/rest.py", line 322, in submit_order
    resp = self.post('/orders', params)
  File "/usr/local/lib/python3.7/site-packages/alpaca_trade_api/rest.py", line 165, in post
    return self._request('POST', path, data)
  File "/usr/local/lib/python3.7/site-packages/alpaca_trade_api/rest.py", line 125, in _request
    return self._one_request(method, url, opts, retry)
  File "/usr/local/lib/python3.7/site-packages/alpaca_trade_api/rest.py", line 154, in _one_request
    raise APIError(error, http_error)
alpaca_trade_api.rest.APIError: limit orders require a limit price
2021-02-05 10:55:02,475:ERROR:ORDER NOT SENT
Traceback (most recent call last):
  File "/usr/local/lib/python3.7/site-packages/alpaca_trade_api/rest.py", line 146, in _one_request
    resp.raise_for_status()
  File "/usr/lib/python3.7/site-packages/requests/models.py", line 940, in raise_for_status
    raise HTTPError(http_error_msg, response=self)
requests.exceptions.HTTPError: 422 Client Error: Unprocessable Entity for url: https://paper-api.alpaca.markets/v2/orders

During handling of the above exception, another exception occurred:

Traceback (most recent call last):
  File "/home/will/Documents/Development/Alpaca/python/example.py", line 125, in send_order
    take_profit=dict(limit_price=str(tp)),
  File "/usr/local/lib/python3.7/site-packages/alpaca_trade_api/rest.py", line 322, in submit_order
    resp = self.post('/orders', params)
  File "/usr/local/lib/python3.7/site-packages/alpaca_trade_api/rest.py", line 165, in post
    return self._request('POST', path, data)
  File "/usr/local/lib/python3.7/site-packages/alpaca_trade_api/rest.py", line 125, in _request
    return self._one_request(method, url, opts, retry)
  File "/usr/local/lib/python3.7/site-packages/alpaca_trade_api/rest.py", line 154, in _one_request
    raise APIError(error, http_error)
alpaca_trade_api.rest.APIError: limit orders require a limit price
2021-02-05 11:02:02,339:ERROR:ORDER NOT SENT
Traceback (most recent call last):
  File "/usr/local/lib/python3.7/site-packages/alpaca_trade_api/rest.py", line 146, in _one_request
    resp.raise_for_status()
  File "/usr/lib/python3.7/site-packages/requests/models.py", line 940, in raise_for_status
    raise HTTPError(http_error_msg, response=self)
requests.exceptions.HTTPError: 422 Client Error: Unprocessable Entity for url: https://paper-api.alpaca.markets/v2/orders

During handling of the above exception, another exception occurred:

Traceback (most recent call last):
  File "/home/will/Documents/Development/Alpaca/python/example.py", line 125, in send_order
    take_profit=dict(limit_price=str(tp)),
  File "/usr/local/lib/python3.7/site-packages/alpaca_trade_api/rest.py", line 322, in submit_order
    resp = self.post('/orders', params)
  File "/usr/local/lib/python3.7/site-packages/alpaca_trade_api/rest.py", line 165, in post
    return self._request('POST', path, data)
  File "/usr/local/lib/python3.7/site-packages/alpaca_trade_api/rest.py", line 125, in _request
    return self._one_request(method, url, opts, retry)
  File "/usr/local/lib/python3.7/site-packages/alpaca_trade_api/rest.py", line 154, in _one_request
    raise APIError(error, http_error)
alpaca_trade_api.rest.APIError: limit orders require a limit price
2021-02-05 11:03:02,388:ERROR:ORDER NOT SENT
Traceback (most recent call last):
  File "/usr/local/lib/python3.7/site-packages/alpaca_trade_api/rest.py", line 146, in _one_request
    resp.raise_for_status()
  File "/usr/lib/python3.7/site-packages/requests/models.py", line 940, in raise_for_status
    raise HTTPError(http_error_msg, response=self)
requests.exceptions.HTTPError: 422 Client Error: Unprocessable Entity for url: https://paper-api.alpaca.markets/v2/orders

During handling of the above exception, another exception occurred:

Traceback (most recent call last):
  File "/home/will/Documents/Development/Alpaca/python/example.py", line 125, in send_order
    take_profit=dict(limit_price=str(tp)),
  File "/usr/local/lib/python3.7/site-packages/alpaca_trade_api/rest.py", line 322, in submit_order
    resp = self.post('/orders', params)
  File "/usr/local/lib/python3.7/site-packages/alpaca_trade_api/rest.py", line 165, in post
    return self._request('POST', path, data)
  File "/usr/local/lib/python3.7/site-packages/alpaca_trade_api/rest.py", line 125, in _request
    return self._one_request(method, url, opts, retry)
  File "/usr/local/lib/python3.7/site-packages/alpaca_trade_api/rest.py", line 154, in _one_request
    raise APIError(error, http_error)
alpaca_trade_api.rest.APIError: limit orders require a limit price
2021-02-05 11:04:02,363:ERROR:ORDER NOT SENT
Traceback (most recent call last):
  File "/usr/local/lib/python3.7/site-packages/alpaca_trade_api/rest.py", line 146, in _one_request
    resp.raise_for_status()
  File "/usr/lib/python3.7/site-packages/requests/models.py", line 940, in raise_for_status
    raise HTTPError(http_error_msg, response=self)
requests.exceptions.HTTPError: 422 Client Error: Unprocessable Entity for url: https://paper-api.alpaca.markets/v2/orders

During handling of the above exception, another exception occurred:

Traceback (most recent call last):
  File "/home/will/Documents/Development/Alpaca/python/example.py", line 125, in send_order
    take_profit=dict(limit_price=str(tp)),
  File "/usr/local/lib/python3.7/site-packages/alpaca_trade_api/rest.py", line 322, in submit_order
    resp = self.post('/orders', params)
  File "/usr/local/lib/python3.7/site-packages/alpaca_trade_api/rest.py", line 165, in post
    return self._request('POST', path, data)
  File "/usr/local/lib/python3.7/site-packages/alpaca_trade_api/rest.py", line 125, in _request
    return self._one_request(method, url, opts, retry)
  File "/usr/local/lib/python3.7/site-packages/alpaca_trade_api/rest.py", line 154, in _one_request
    raise APIError(error, http_error)
alpaca_trade_api.rest.APIError: limit orders require a limit price
2021-02-05 11:05:02,606:ERROR:ORDER NOT SENT
Traceback (most recent call last):
  File "/usr/local/lib/python3.7/site-packages/alpaca_trade_api/rest.py", line 146, in _one_request
    resp.raise_for_status()
  File "/usr/lib/python3.7/site-packages/requests/models.py", line 940, in raise_for_status
    raise HTTPError(http_error_msg, response=self)
requests.exceptions.HTTPError: 422 Client Error: Unprocessable Entity for url: https://paper-api.alpaca.markets/v2/orders

During handling of the above exception, another exception occurred:

Traceback (most recent call last):
  File "/home/will/Documents/Development/Alpaca/python/example.py", line 125, in send_order
    take_profit=dict(limit_price=str(tp)),
  File "/usr/local/lib/python3.7/site-packages/alpaca_trade_api/rest.py", line 322, in submit_order
    resp = self.post('/orders', params)
  File "/usr/local/lib/python3.7/site-packages/alpaca_trade_api/rest.py", line 165, in post
    return self._request('POST', path, data)
  File "/usr/local/lib/python3.7/site-packages/alpaca_trade_api/rest.py", line 125, in _request
    return self._one_request(method, url, opts, retry)
  File "/usr/local/lib/python3.7/site-packages/alpaca_trade_api/rest.py", line 154, in _one_request
    raise APIError(error, http_error)
alpaca_trade_api.rest.APIError: limit orders require a limit price
2021-02-05 11:06:02,539:ERROR:ORDER NOT SENT
Traceback (most recent call last):
  File "/usr/local/lib/python3.7/site-packages/alpaca_trade_api/rest.py", line 146, in _one_request
    resp.raise_for_status()
  File "/usr/lib/python3.7/site-packages/requests/models.py", line 940, in raise_for_status
    raise HTTPError(http_error_msg, response=self)
requests.exceptions.HTTPError: 422 Client Error: Unprocessable Entity for url: https://paper-api.alpaca.markets/v2/orders

During handling of the above exception, another exception occurred:

Traceback (most recent call last):
  File "/home/will/Documents/Development/Alpaca/python/example.py", line 125, in send_order
    take_profit=dict(limit_price=str(tp)),
  File "/usr/local/lib/python3.7/site-packages/alpaca_trade_api/rest.py", line 322, in submit_order
    resp = self.post('/orders', params)
  File "/usr/local/lib/python3.7/site-packages/alpaca_trade_api/rest.py", line 165, in post
    return self._request('POST', path, data)
  File "/usr/local/lib/python3.7/site-packages/alpaca_trade_api/rest.py", line 125, in _request
    return self._one_request(method, url, opts, retry)
  File "/usr/local/lib/python3.7/site-packages/alpaca_trade_api/rest.py", line 154, in _one_request
    raise APIError(error, http_error)
alpaca_trade_api.rest.APIError: limit orders require a limit price
2021-02-05 11:07:02,413:ERROR:ORDER NOT SENT
Traceback (most recent call last):
  File "/usr/local/lib/python3.7/site-packages/alpaca_trade_api/rest.py", line 146, in _one_request
    resp.raise_for_status()
  File "/usr/lib/python3.7/site-packages/requests/models.py", line 940, in raise_for_status
    raise HTTPError(http_error_msg, response=self)
requests.exceptions.HTTPError: 422 Client Error: Unprocessable Entity for url: https://paper-api.alpaca.markets/v2/orders

During handling of the above exception, another exception occurred:

Traceback (most recent call last):
  File "/home/will/Documents/Development/Alpaca/python/example.py", line 123, in send_order
    order_class='simple',
  File "/usr/local/lib/python3.7/site-packages/alpaca_trade_api/rest.py", line 322, in submit_order
    resp = self.post('/orders', params)
  File "/usr/local/lib/python3.7/site-packages/alpaca_trade_api/rest.py", line 165, in post
    return self._request('POST', path, data)
  File "/usr/local/lib/python3.7/site-packages/alpaca_trade_api/rest.py", line 125, in _request
    return self._one_request(method, url, opts, retry)
  File "/usr/local/lib/python3.7/site-packages/alpaca_trade_api/rest.py", line 154, in _one_request
    raise APIError(error, http_error)
alpaca_trade_api.rest.APIError: limit orders require a limit price
